<?xml version="1.0"?>
<robot xmlns:xacro="http://www.ros.org/wiki/xacro" name="rover">

<xacro:include filename="$(find mobile_robot)/urdf/rov_gazebo_stl.gazebo" />
<xacro:include filename="$(find mobile_robot)/urdf/rov_gazebo_stl.trans" />
<xacro:include filename="$(find mobile_robot)/urdf/rov_gazebo_stl_materials.xacro" />

    <link name="base_footprint"/>
    <link name="base_link">
        <inertial>
            <origin xyz="0.0 0.0 0.0" rpy="0.0 0.0 0.0"/>
            <mass value="1.0"/>
            <inertia ixx="0.04165" ixy="0.0" ixz="0.0" iyy="0.054145" iyz="0.0" izz="0.094129"/>
        </inertial>
        <visual name="">
            <origin xyz="0.0 0.0 0.0" rpy="0.0 0.0 0.0"/>
            <geometry>
                <box size="0.8 0.7 0.2"/>
            </geometry>
            <material name="">
                <color rgba="1.0 1.0 1.0 1.0"/>
                <texture filename=""/>
            </material>
        </visual>
        <collision>
            <origin xyz="0.0 0.0 0.0" rpy="0.0 0.0 0.0"/>
            <geometry>
                <box size="0.0 0.0 0.0"/>
            </geometry>
        </collision>
    </link>
    <joint name="base_joint" type="fixed">
        <origin xyz="0.0 0.0 0.135" rpy="0.0 0.0 3.14"/>
        <parent link="base_footprint"/>
        <child link="base_link"/>
        <axis xyz="0.0 0.0 0.0"/>
    </joint>
    


    <link name="wheel_rear_right_link">
        <inertial>
            <origin xyz="0.0 0.0 0.0" rpy="0.0 0.0 0.0"/>
            <mass value="0.5"/>
            <inertia ixx="0.003227875" ixy="0.0" ixz="0.0" iyy="0.003227875" iyz="0.0" izz="0.005625"/>
        </inertial>
        <visual name="">
            <origin xyz="0.0 0.0 0.0" rpy="0.0 0.0 0.0"/>
            <geometry>
                <mesh filename="package://mobile_robot/meshes/right_tire.stl" scale="0.005 0.005 0.005"/>
            </geometry>
            <material name="red">
                <color rgba="1.0 0.0 0.0 1.0"/>
                <texture filename=""/>
            </material>
        </visual>
        <collision>
            <origin xyz="0.0 0.0 0.0" rpy="0.0 0.0 0.0"/>
            <geometry>
                <mesh filename="package://mobile_robot/meshes/right_tire.stl" scale="0.005 0.005 0.005"/>
            </geometry>
        </collision>
    </link>

    <joint name="wheel_rear_right_joint" type="continuous">
        <origin xyz="0.25 0.40 0.0" rpy="0.0 0.0 0.0"/>
        <parent link="base_link"/>
        <child link="wheel_rear_right_link"/>
        <axis xyz="0.0 -1.0 0.0"/>
        <limit lower="0.0" upper="0.0" effort="0.0" velocity="0.0"/>
    </joint>

     <link name="wheel_rear_left_link">
        <inertial>
            <origin xyz="0.0 0.0 0.0" rpy="0.0 0.0 0.0"/>
            <mass value="0.5"/>
            <inertia ixx="0.003227875" ixy="0.0" ixz="0.0" iyy="0.003227875" iyz="0.0" izz="0.005625"/>
        </inertial>
        <visual name="">
            <origin xyz="0.0 0.0 0.0" rpy="0.0 0.0 0.0"/>
            <geometry>
               <mesh filename="package://mobile_robot/meshes/left_tire.stl" scale="0.005 0.005 0.005"/>
            </geometry>
            <material name="red">
                <color rgba="1.0 0.0 0.0 1.0"/>
                <texture filename=""/>
            </material>
        </visual>
        <collision>
            <origin xyz="0.0 0.0 0.0" rpy="0.0 0.0 0.0"/>
            <geometry>
                <mesh filename="package://mobile_robot/meshes/left_tire.stl" scale="0.005 0.005 0.005"/>
            </geometry>
        </collision>
    </link>

    <joint name="wheel_rear_left_joint" type="continuous">
        <origin xyz="0.25 -0.40 0.0" rpy="0.0 0.0 0.0"/>
        <parent link="base_link"/>
        <child link="wheel_rear_left_link"/>
        <axis xyz="0.0 -1.0 0.0"/>
        <limit lower="0.0" upper="0.0" effort="0.0" velocity="0.0"/>
    </joint>

     <link name="wheel_front_right_link">
        <inertial>
            <origin xyz="0.0 0.0 0.0" rpy="0.0 0.0 0.0"/>
            <mass value="0.5"/>
            <inertia ixx="0.003227875" ixy="0.0" ixz="0.0" iyy="0.003227875" iyz="0.0" izz="0.005625"/>
        </inertial>
        <visual name="">
            <origin xyz="0.0 0.0 0.0" rpy="0.0 0.0 0.0"/>
            <geometry>
                <mesh filename="package://mobile_robot/meshes/right_tire.stl" scale="0.005 0.005 0.005"/>
            </geometry>
            <material name="rec">
                <color rgba="1.0 0.0 0.0 1.0"/>
                <texture filename=""/>
            </material>
        </visual>
        <collision>
            <origin xyz="0.0 0.0 0.0" rpy="0.0 0.0 0.0"/>
            <geometry>
                <mesh filename="package://mobile_robot/meshes/right_tire.stl" scale="0.005 0.005 0.005"/>
            </geometry>
        </collision>
    </link>

    <joint name="wheel_front_right_joint" type="continuous">
        <origin xyz="-0.25 0.40 0.0" rpy="0.0 0.0 0.0"/>
        <parent link="base_link"/>
        <child link="wheel_front_right_link"/>
        <axis xyz="0.0 -1.0 0.0"/>
        <limit lower="0.0" upper="0.0" effort="0.0" velocity="0.0"/>
    </joint>

     <link name="wheel_front_left_link">
        <inertial>
            <origin xyz="0.0 0.0 0.0" rpy="0.0 0.0 0.0"/>
            <mass value="0.5"/>
            <inertia ixx="0.003227875" ixy="0.0" ixz="0.0" iyy="0.003227875" iyz="0.0" izz="0.005625"/>
        </inertial>
        <visual name="">
            <origin xyz="0.0 0.0 0.0" rpy="0.0 0.0 0.0"/>
            <geometry>
                <mesh filename="package://mobile_robot/meshes/left_tire.stl" scale="0.005 0.005 0.005"/>
            </geometry>
            <material name="red">
                <color rgba="1.0 0.0 0.0 1.0"/>
                <texture filename=""/>
            </material>
        </visual>
        <collision>
            <origin xyz="0.0 0.0 0.0" rpy="0.0 0.0 0.0"/>
            <geometry>
                <mesh filename="package://mobile_robot/meshes/left_tire.stl" scale="0.005 0.005 0.005"/>
            </geometry>
        </collision>
    </link>

    <joint name="wheel_front_left_joint" type="continuous">
        <origin xyz="-0.25 -0.40 0.0" rpy="0.0 0.0 0.0"/>
        <parent link="base_link"/>
        <child link="wheel_front_left_link"/>
        <axis xyz="0.0 -1.0 0.0"/>
        <limit lower="0.0" upper="0.0" effort="0.0" velocity="0.0"/>
    </joint>

    <link name="camera_link">
        <inertial>
            <origin xyz="0.0 0.0 0.0" rpy="0.0 0.0 0.0"/>
            <mass value="0.2"/>
            <inertia ixx="0.0003332" ixy="0.0" ixz="0.0" iyy="0.000833" iyz="0.0" izz="0.000833"/>
        </inertial>
        <visual name="">
            <origin xyz="0.0 0.0 0.1" rpy="0.0 0.0 0.0"/>
            <geometry>
                <box size="0.1 0.2 0.1"/>
            </geometry>
            <material name="red">
                <color rgba="1.0 0.0 0.0 1.0"/>
                <texture filename=""/>
            </material>
        </visual>
        <collision>
            <origin xyz="0.0 0.0 0.0" rpy="0.0 0.0 0.0"/>
            <geometry>
                <box size="0.1 0.1 0.1"/>
            </geometry>
        </collision>
    </link>

    <joint name="camera_joint" type="fixed">
        <origin xyz="-0.3 0.0 0.05" rpy="0.0 0.0 3.14"/>
        <parent link="base_link"/>
        <child link="camera_link"/>
        <axis xyz="0.0 0.0 0.0"/>
        <limit lower="0.0" upper="0.0" effort="0.0" velocity="0.0"/>
    </joint>
    
    <link name="lidar">
        <inertial>
            <origin xyz="0.0 0.0 0.0" rpy="0.0 0.0 0.0"/>
            <mass value="0.4"/>
            <inertia ixx="0.0035833" ixy="0.0" ixz="0.0" iyy="0.0035833" iyz="0.0" izz="0.0045"/>
        </inertial>
        <visual name="">
            <origin xyz="0.0 0.0 0.0" rpy="0.0 0.0 0.0"/>
            <geometry>
                <cylinder radius="0.15" length="0.2"/>
            </geometry>
            <material name="red">
                <color rgba="1.0 0.0 0.0 1.0"/>
                <texture filename=""/>
            </material>
        </visual>
        <!--<collision>
            <origin xyz="0.0 0.0 0.0" rpy="0.0 0.0 0.0"/>
            <geometry>
                <cylinder radius="0.15" length="0.2"/>
            </geometry>
        </collision>-->
    </link>

    <joint name="lidar_joint" type="fixed">
        <origin xyz="0.0 0.0 0.2" rpy="0.0 0.0 3.14"/>
        <parent link="base_link"/>
        <child link="lidar"/>
        <axis xyz="0.0 0.0 0.0"/>
        <limit lower="0.0" upper="0.0" effort="0.0" velocity="0.0"/>
    </joint>
</robot> 